<?xml version="1.0" encoding="utf-8"?>
<!-- This URDF was automatically created by SolidWorks to URDF Exporter! Originally created by Stephen Brawner (brawner@gmail.com) 
     Commit Version: 1.6.0-1-g15f4949  Build Version: 1.6.7594.29634
     For more information, please see http://wiki.ros.org/sw_urdf_exporter -->
<robot
  name="puma560_description" xmlns:xacro="http://www.ros.org/wiki/xacro">
  <!-- Puma 560 description.-->
  <link
    name="world">
    <visual>
      <origin
        xyz="0 0 0"
        rpy="0 0 0" />
      <geometry>
        <box size="0.0 0.0 0.0"/>  
      </geometry>
    </visual>
  </link>
  <link
    name="base_link">
    <inertial>
      <origin
        xyz="-0.12618 -0.038304 -0.022005"
        rpy="0 0 0" />
      <mass
        value="15.807" />
      <inertia
        ixx="0.55024"
        ixy="-1.5584E-10"
        ixz="2.6401E-11"
        iyy="0.16071"
        iyz="-0.022162"
        izz="0.50424" />
    </inertial>
    <visual>
      <origin
        xyz="0 0 0"
        rpy="0 0 0" />
      <geometry>
        <mesh
          filename="package://puma560_description/meshes/base_link.STL" />
      </geometry>
      <material
        name="">
        <color
          rgba="1 1 1 1" />
      </material>
    </visual>
    <collision>
      <origin
        xyz="0 0 0"
        rpy="0 0 0" />
      <geometry>
        <mesh
          filename="package://puma560_description/meshes/base_link.STL" />
      </geometry>
    </collision>
  </link>
  <joint
    name="j0"
    type="fixed">
    <origin
      xyz="0 0 0.23"
      rpy="0 0 0" />
    <parent
      link="world" />
    <child
      link="base_link" />
  </joint>
  <link
    name="link_1">
    <inertial>
      <origin
        xyz="-0.022505 -0.07849 -3.2256E-07"
        rpy="0 0 0" />
      <mass
        value="4.4341" />
      <inertia
        ixx="0.013316"
        ixy="-0.00027859"
        ixz="-1.214E-07"
        iyy="0.027164"
        iyz="2.346E-07"
        izz="0.027328" />
    </inertial>
    <visual>
      <origin
        xyz="0 0 0"
        rpy="0 0 0" />
      <geometry>
        <mesh
          filename="package://puma560_description/meshes/link_1.STL" />
      </geometry>
      <material
        name="">
        <color
          rgba="1 1 1 1" />
      </material>
    </visual>
    <collision>
      <origin
        xyz="0 0 0"
        rpy="0 0 0" />
      <geometry>
        <mesh
          filename="package://puma560_description/meshes/link_1.STL" />
      </geometry>
    </collision>
  </link>
  <joint
    name="j1"
    type="revolute">
    <origin
      xyz="-0.12618 0 0.31169"
      rpy="-1.5708 0 1.3815" />
    <parent
      link="base_link" />
    <child
      link="link_1" />
    <axis
      xyz="0 1 0" />
    <limit
      lower="-3.1416"
      upper="3.1416"
      effort="1000"
      velocity="0.5" />
  </joint>
  <link
    name="link_2">
    <inertial>
      <origin
        xyz="-0.068869 -4.6775E-05 0.082737"
        rpy="0 0 0" />
      <mass
        value="16.847" />
      <inertia
        ixx="0.65976"
        ixy="4.8383E-05"
        ixz="0.0043475"
        iyy="0.59657"
        iyz="-7.8848E-06"
        izz="0.09723" />
    </inertial>
    <visual>
      <origin
        xyz="0 0 0"
        rpy="0 0 0" />
      <geometry>
        <mesh
          filename="package://puma560_description/meshes/link_2.STL" />
      </geometry>
      <material
        name="">
        <color
          rgba="0.79216 0.81961 0.93333 1" />
      </material>
    </visual>
    <collision>
      <origin
        xyz="0 0 0"
        rpy="0 0 0" />
      <geometry>
        <mesh
          filename="package://puma560_description/meshes/link_2.STL" />
      </geometry>
    </collision>
  </link>
  <joint
    name="j2"
    type="revolute">
    <origin
      xyz="-0.14641 -0.08128 0"
      rpy="3.0346 0 0" />
    <parent
      link="link_1" />
    <child
      link="link_2" />
    <axis
      xyz="1 0 0" />
    <limit
      lower="-1.5707"
      upper="1.5707"
      effort="1000"
      velocity="0.5" />
  </joint>
  <link
    name="link_3">
    <inertial>
      <origin
        xyz="-0.01687 -0.088774 -1.1788E-06"
        rpy="0 0 0" />
      <mass
        value="4.6025" />
      <inertia
        ixx="0.087355"
        ixy="-2.2739E-06"
        ixz="3.6529E-07"
        iyy="0.0091916"
        iyz="-4.837E-07"
        izz="0.082615" />
    </inertial>
    <visual>
      <origin
        xyz="0 0 0"
        rpy="0 0 0" />
      <geometry>
        <mesh
          filename="package://puma560_description/meshes/link_3.STL" />
      </geometry>
      <material
        name="">
        <color
          rgba="1 1 1 1" />
      </material>
    </visual>
    <collision>
      <origin
        xyz="0 0 0"
        rpy="0 0 0" />
      <geometry>
        <mesh
          filename="package://puma560_description/meshes/link_3.STL" />
      </geometry>
    </collision>
  </link>
  <joint
    name="j3"
    type="revolute">
    <origin
      xyz="0 0 0.4318"
      rpy="-2.6879 0 -3.1416" />
    <parent
      link="link_2" />
    <child
      link="link_3" />
    <axis
      xyz="1 0 0" />
    <limit
      lower="-1.5707"
      upper="1.5707"
      effort="1000"
      velocity="0.5" />
  </joint>
  <link
    name="link_4">
    <inertial>
      <origin
        xyz="1.1102E-16 -0.0067199 2.7756E-17"
        rpy="0 0 0" />
      <mass
        value="0.47079" />
      <inertia
        ixx="0.00077289"
        ixy="-1.7279E-19"
        ixz="-5.421E-20"
        iyy="0.00046683"
        iyz="1.5585E-19"
        izz="0.00073772" />
    </inertial>
    <visual>
      <origin
        xyz="0 0 0"
        rpy="0 0 0" />
      <geometry>
        <mesh
          filename="package://puma560_description/meshes/link_4.STL" />
      </geometry>
      <material
        name="">
        <color
          rgba="0.25098 0.25098 0.25098 1" />
      </material>
    </visual>
    <collision>
      <origin
        xyz="0 0 0"
        rpy="0 0 0" />
      <geometry>
        <mesh
          filename="package://puma560_description/meshes/link_4.STL" />
      </geometry>
    </collision>
  </link>
  <joint
    name="j4"
    type="revolute">
    <origin
      xyz="-0.016872 -0.39296 0"
      rpy="3.1416 -1.2686 3.1416" />
    <parent
      link="link_3" />
    <child
      link="link_4" />
    <axis
      xyz="0 1 0" />
    <limit
      lower="-1.5707"
      upper="1.5707"
      effort="1000"
      velocity="0.5" />
  </joint>
  <link
    name="link_5">
    <inertial>
      <origin
        xyz="6.6543E-10 -3.7332E-09 0.010974"
        rpy="0 0 0" />
      <mass
        value="0.077406" />
      <inertia
        ixx="4.5414E-05"
        ixy="1.1361E-11"
        ixz="-6.3669E-13"
        iyy="4.3032E-05"
        iyz="2.5557E-12"
        izz="1.6966E-05" />
    </inertial>
    <visual>
      <origin
        xyz="0 0 0"
        rpy="0 0 0" />
      <geometry>
        <mesh
          filename="package://puma560_description/meshes/link_5.STL" />
      </geometry>
      <material
        name="">
        <color
          rgba="0.79216 0.81961 0.93333 1" />
      </material>
    </visual>
    <collision>
      <origin
        xyz="0 0 0"
        rpy="0 0 0" />
      <geometry>
        <mesh
          filename="package://puma560_description/meshes/link_5.STL" />
      </geometry>
    </collision>
  </link>
  <joint
    name="j5"
    type="revolute">
    <origin
      xyz="0 -0.039129 0"
      rpy="1.4855 1.5708 0" />
    <parent
      link="link_4" />
    <child
      link="link_5" />
    <axis
      xyz="1 0 0" />
    <limit
      lower="-1.5707"
      upper="1.5707"
      effort="1000"
      velocity="0.5" />
  </joint>

  <!-- Transmission-->
  <transmission name="trans_j1">
    <type>transmission_interface/SimpleTransmission</type>
    <joint name="j1">
      <hardwareInterface>EffortJointInterface</hardwareInterface>
    </joint>
    <actuator name="motor_j1">
      <hardwareInterface>EffortJointInterface</hardwareInterface>
      <mechanicalReduction>1</mechanicalReduction>
    </actuator>
  </transmission>

  <transmission name="trans_j2">
    <type>transmission_interface/SimpleTransmission</type>
    <joint name="j2">
      <hardwareInterface>EffortJointInterface</hardwareInterface>
    </joint>
    <actuator name="motor_j2">
      <hardwareInterface>EffortJointInterface</hardwareInterface>
      <mechanicalReduction>1</mechanicalReduction>
    </actuator>
  </transmission>

  <transmission name="trans_j3">
    <type>transmission_interface/SimpleTransmission</type>
    <joint name="j3">
      <hardwareInterface>EffortJointInterface</hardwareInterface>
    </joint>
    <actuator name="motor_j3">
      <hardwareInterface>EffortJointInterface</hardwareInterface>
      <mechanicalReduction>1</mechanicalReduction>
    </actuator>
  </transmission>

  <transmission name="trans_j4">
    <type>transmission_interface/SimpleTransmission</type>
    <joint name="j4">
      <hardwareInterface>EffortJointInterface</hardwareInterface>
    </joint>
    <actuator name="motor_j4">
      <hardwareInterface>EffortJointInterface</hardwareInterface>
      <mechanicalReduction>1</mechanicalReduction>
    </actuator>
  </transmission>

  <transmission name="trans_j5">
    <type>transmission_interface/SimpleTransmission</type>
    <joint name="j5">
      <hardwareInterface>EffortJointInterface</hardwareInterface>
    </joint>
    <actuator name="motor_j5">
      <hardwareInterface>EffortJointInterface</hardwareInterface>
      <mechanicalReduction>1</mechanicalReduction>
    </actuator>
  </transmission>

  <!-- Gazebo plugin. -->
  <gazebo>
    <plugin name="gazebo_ros_control" filename="libgazebo_ros_control.so">
      <robotNamespace>/puma560_description</robotNamespace>
    </plugin>
  </gazebo>
</robot>